Workbook
Name ACTION: #REF!
Name ACTION: #REF!

Sheet Cover
B2: TEST REPORT DOCUMENT
A4: Project Name | B4: EduBus School Bus Management System | E4: Creator | F4: NhiPTK
A5: Project Code | B5: ESBMS | E5: Issue Date | F5: 45912
A6: Document Code | B6: =B5&"_"&"Test Report"&"_"&"v1.0" -> ESBMS_Test Report_v1.0 | E6: Version
A9: Record of change
A10: Effective Date | B10: Version | C10: Change Item | D10: *A,D,M | E10: Change description | F10: Reference
A11: 45912 | B11: 1.0 | C11: Initial Test Requirements | D11: A | E11: - Add initial test requirements - Define overall project scope
A12: 45912 | B12: 1.1 | C12: Project Scope Update | D12: M | E12: - Update project scope based on instructor feedback
A13: 45913 | B13: 1.2 | C13: Functional Requirements Update | D13: M | E13: - Modify and refine functional requirements
A14: 45913 | B14: 1.3 | C14: Test Case Refinement | D14: M | E14: - Improve test cases and test scenarios
A15: 45914 | B15: 1.4 | C15: Final Project Update | D15: M | E15: - Finalize documentation and update project content

Sheet Test Cases
D1: TEST CASE LIST
B3: Project Name | D3: EduBus School Bus Management System
B4: Project Code | D4: ESBMS
B5: Test Environment Setup Description | D5: 1. Server 2. Database 3. Web Browser
B8: No | C8: Function Name | D8: Sheet Name | E8: Description | F8: Pre-Condition
B9: 1 | C9: Login | D9: User Account Management | E9: Allow users to log into the system with valid credentials. | F9: Must connect with server
B10: 2 | C10: Logout | D10: User Account Management | E10: Allow users to securely log out of the system. | F10: Must connect with server
B11: 3 | C11: Change password | D11: User Account Management | E11: Users can change their current password to a new one. | F11: Must connect with server
B12: 4 | C12: Forgot password | D12: User Account Management | E12: Allow users to reset their password via email/OTP. | F12: Must connect with server
B13: 5 | C13: Edit personal profile | D13: User Account Management | E13: Allow users to update their personal information. | F13: Must connect with server
B14: 6 | C14: View personal profile | D14: User Account Management | E14: Display user’s personal information. | F14: Must connect with server
B15: 7 | C15: Create user accounts | D15: User Account Management | E15: Allow admins to create new user accounts. | F15: Must connect with server
B16: 8 | C16: Import driver/parent file | D16: User Account Management | E16: Allow admins to bulk-import users from a file. | F16: Must connect with server
B17: 9 | C17: View user list | D17: User Account Management | E17: Display the list of all system users. | F17: Must connect with server
B18: 10 | C18: Ban/Unban users | D18: User Account Management | E18: Allow admins to restrict or restore user access. | F18: Must connect with server
B19: 11 | C19: Upload user avatar | D19: User Account Management | E19: Allow users to upload or change their profile picture. | F19: Must connect with server
B20: 12 | C20: View driver’s information (Parent) | D20: User Account Management | E20: Display assigned driver details for parents. | F20: Must connect with server
... B90: 85 | C90: Delete unit price | D90: School System Configuration | E90: Allow admins to remove pricing items. | F90: Must connect with server

Sheet Test Statistics
B1: TEST STATISTICS
B3: Project Name | C3: EduBus School Bus Management System | E3: Creator | H3: HuyNLQ, NguyetNTT, TrungNVT, NhiPTK, KhoiVN
B4: Project Code | C4: ESBMS | E4: Reviewer/Approver
B5: Document Code | C5: =C4&"_"&"Test Report"&"_"&"1.0" -> ESBMS_Test Report_1.0 | E5: Issue Date | H5: 45912
B6: Notes
B10: No | C10: Module code | D10: Passed | E10: Failed | F10: Pending | G10: N/A | H10: Number of test cases
B11: 1 | C11: ='User Account Management'!B2 -> User Account Management | D11: ='User Account Management'!B8 -> 109 | E11: ='User Account Management'!C8 -> 1 | F11: ='User Account Management'!D6 -> 0 | G11: ='User Account Management'!E6 -> 1 | H11: ='User Account Management'!B4 -> 112
B12: 2 | C12: ='Service Registration & Payment'!B2 -> Service Registration & Payment | D12: ='Service Registration & Payment'!B8 -> 24 | E12: ='Service Registration & Payment'!C8 -> 0 | F12: ='Service Registration & Payment'!D6 -> 0 | G12: ='Service Registration & Payment'!E6 -> 0 | H12: ='Service Registration & Payment'!B4 -> 26
B13: 3 | C13: ='Student Management'!B2 -> Student management | D13: ='Student Management'!B8 -> 41 | E13: ='Student Management'!C8 -> 0 | F13: ='Student Management'!D8 -> 0 | G13: ='Student Management'!E6 -> 1 | H13: ='Student Management'!B4 -> 44
B14: 4 | C14: ='Vehicle Management'!B2 -> Verifies the complete vehicle management flow—including registering, editing, assigning, monitoring, and deactivating vehicles—covering input validation, operational constraints, assignment consistency, safety parameters, and role-based permissions. | D14: ='Vehicle Management'!B8 -> 22 | E14: ='Vehicle Management'!C8 -> 3 | F14: ='Vehicle Management'!D8 -> 2 | G14: ='Vehicle Management'!E6 -> 0 | H14: ='Vehicle Management'!B4 -> 27
B15: 5 | C15: ='Route Management'!B2 -> Route Management | D15: ='Route Management'!B8 -> 54 | E15: ='Route Management'!C8 -> 0 | F15: ='Route Management'!D8 -> 0 | G15: ='Route Management'!E6 -> 0 | H15: ='Route Management'!B4 -> 54
B16: 6 | C16: ='Schedule Management'!B2 -> Schedule Management | D16: ='Schedule Management'!B8 -> 122 | E16: ='Schedule Management'!C8 -> 3 | F16: ='Schedule Management'!D7 -> 0 | G16: ='Schedule Management'!E7 -> 0 | H16: ='Schedule Management'!B4 -> 125
B17: 7 | C17: ='Trip Management'!B2 -> Trip Management | D17: ='Trip Management'!B8 -> 52 | E17: ='Trip Management'!C8 -> 0 | F17: ='Trip Management'!D6 -> 0 | G17: ='Trip Management'!E6 -> 0 | H17: ='Trip Management'!B4 -> 52
B18: 8 | C18: ='Atendance Management'!B2 -> Attendance Management | D18: ='Atendance Management'!B8 -> 38 | E18: ='Atendance Management'!C8 -> 0 | F18: ='Atendance Management'!D6 -> 0 | G18: ='Atendance Management'!E6 -> 0 | H18: ='Atendance Management'!B4 -> 38
B19: 9 | C19: ='Vehicle Status Monitoring'!B2 -> Vehicle Status Monitoring | D19: ='Vehicle Status Monitoring'!B8 -> 9 | E19: ='Vehicle Status Monitoring'!C8 -> 0 | F19: ='Vehicle Status Monitoring'!D6 -> 0 | G19: ='Vehicle Status Monitoring'!E6 -> 0 | H19: ='Vehicle Status Monitoring'!B4 -> 12
B20: 10 | C20: =Notifications!B2 -> Notifications | D20: =Notifications!B8 -> 10 | E20: =Notifications!C8 -> 2 | F20: =Notifications!D6 -> 0 | G20: =Notifications!E6 -> 0 | H20: =Notifications!B4 -> 12
B21: 11 | C21: ='PickupDrop-off Address Manageme'!B2 -> Pickup/Drop-off Address Management | D21: ='PickupDrop-off Address Manageme'!B8 -> 8 | E21: ='PickupDrop-off Address Manageme'!C8 -> 0 | F21: ='PickupDrop-off Address Manageme'!D6 -> 0 | G21: ='PickupDrop-off Address Manageme'!E6 -> 0 | H21: ='PickupDrop-off Address Manageme'!B4 -> 10
B22: 12 | C22: =Reporting!B2 -> Reporting | D22: =Reporting!B8 -> 16 | E22: =Reporting!C8 -> 3 | F22: =Reporting!D6 -> 0 | G22: =Reporting!E6 -> 1 | H22: =Reporting!B4 -> 20
B23: 13 | C23: ='Audit Logs'!B2 -> Audit Logs | D23: ='Audit Logs'!B8 -> 6 | E23: ='Audit Logs'!C8 -> 2 | F23: ='Audit Logs'!D6 -> 0 | G23: ='Audit Logs'!E6 -> 0 | H23: ='Audit Logs'!B4 -> 8
B24: 14 | C24: ='School System Configuration'!B2 -> School System Configuration | D24: ='School System Configuration'!B8 -> 23 | E24: ='School System Configuration'!C8 -> 0 | F24: ='School System Configuration'!D6 -> 1 | G24: ='School System Configuration'!E6 -> 0 | H24: ='School System Configuration'!B4 -> 26
C25: Sub total | D25: =SUM(D11:D24) -> 534 | E25: =SUM(E11:E24) -> 14 | F25: =SUM(F11:F24) -> 3 | G25: =SUM(G11:G24) -> 3 | H25: =SUM(H11:H24) -> 566
C27: Test coverage | E27: =(D25+E25)*100/(H25-G25) -> 97.335702 | F27: %
C28: Test successful coverage | E28: =D25*100/(H25-G25) -> 94.849023 | F28: %

Sheet User Account Management
A2: Feature | B2: User Account Management | R2: Passed
A3: Test requirement | B3: Verifies the full auth flow—register, email/Google login, password reset, and logout—covering input validation, account status checks, security (rate-limit, token/redirect safety), session handling, and graceful error responses. | R3: Failed
A4: Number of TCs | B4: =COUNTA(A12:A1008)-7 -> 112 | R4: Pending
A5: Testing Round | B5: Passed | C5: Failed | D5: Pending | E5: N/A | R5: N/A
A6: Round 1 | B6: =COUNTIF($F10:$F1026,B5) -> 95 | C6: =COUNTIF($F10:$F981,C5) -> 16 | D6: =COUNTIF($F10:$F981,D5) -> 0 | E6: =COUNTIF($F10:$F981,E5) -> 1
A7: Round 2 | B7: =COUNTIF($I10:$I1007,B5) -> 107 | C7: =COUNTIF($I10:$I1007,C5) -> 4 | D7: =COUNTIF($F10:$F981,D5) -> 0 | E7: =COUNTIF($F10:$F981,E5) -> 1
A8: Round 3 | B8: =COUNTIF($L10:$L1007,B5) -> 109 | C8: =COUNTIF($L10:$L1007,C5) -> 1 | D8: =COUNTIF($L10:$L1007,D5) -> 0 | E8: =COUNTIF($F10:$F981,E5) -> 1
A10: Test Case ID | B10: Test Case Description | C10: Test Case Procedure | D10: Expected Results | E10: Pre-conditions | F10: Round 1 | G10: Test date | H10: Tester | I10: Round 2 | J10: Test date | K10: Tester | L10: Round 3 | M10: Test date | N10: Tester | O10: Note
A11: View user lists
A12: VIEW-USERS-001 | B12: View user list with default settings | C12: 1. Login as admin successfully. 2. Navigate to "/admin/users" page. 3. Check user list display. | D12: 1. User list loads successfully. 2. Default 20 users per page are displayed. 3. Users are sorted by first name in ascending order. 4. Pagination controls are visible. 5. Search box and filter options are available. | E12: 1. Admin is logged in. 2. System has users in database. | F12: Passed | G12: 45914 | H12: TrungNVT | I12: Passed | J12: 45954 | K12: HuyNLQ | L12: Passed | M12: 45974 | N12: TrungNVT
A13: VIEW-USERS-002 | B13: View user list with pagination | C13: 1. Login as admin successfully. 2. Navigate to "/admin/users" page. 3. Click "Next" button to go to page 2. 4. Click "Previous" button to go back to page 1. 5. Change items per page to 50. | D13: 1. Page 2 loads with different users. 2. Previous button works correctly. 3. Items per page changes to 50. 4. Pagination controls update correctly. 5. Total page count adjusts properly. | E13: 1. Admin is logged in. 2. System has more than 20 users. | F13: Passed | G13: 45914 | H13: TrungNVT | I13: Passed | J13: 45954 | K13: HuyNLQ | L13: Passed | M13: 45974 | N13: TrungNVT
A14: VIEW-USERS-003 | B14: Search users by name | C14: 1. Login as admin successfully. 2. Navigate to "/admin/users" page. 3. Enter "John" in search box. 4. Press Enter key. 5. Check search results. | D14: 1. Search results show only users with "John" in name. 2. Search is case-insensitive. 3. Results include first name and last name matches. 4. Pagination resets to page 1. 5. Search term is preserved in search box. | E14: 1. Admin is logged in. 2. System has users with name "John". | F14: Passed | G14: 45914 | H14: TrungNVT | I14: Passed | J14: 45954 | K14: HuyNLQ | L14: Passed | M14: 45974 | N14: TrungNVT
A15: VIEW-USERS-004 | B15: Filter users by status - Active | C15: 1. Login as admin successfully. 2. Navigate to "/admin/users" page. 3. Select "Active" from status filter dropdown. 4. Check filtered results. | D15: 1. Only active users are displayed. 2. Locked and deleted users are hidden. 3. User count updates correctly. 4. Pagination adjusts to filtered results. 5. Filter selection is preserved. | E15: 1. Admin is logged in. 2. System has active users. | F15: Passed | G15: 45914 | H15: TrungNVT | I15: Passed | J15: 45954 | K15: HuyNLQ | L15: Passed | M15: 45974 | N15: TrungNVT
A16: VIEW-USERS-005 | B16: Filter users by status - Locked | C16: 1. Login as admin successfully. 2. Navigate to "/admin/users" page. 3. Select "Locked" from status filter dropdown. 4. Check filtered results. | D16: 1. Only locked users are displayed. 2. Active and deleted users are hidden. 3. Lock status is clearly indicated. 4. Lock reason and expiry date are shown. 5. Filter works correctly. | E16: 1. Admin is logged in. 2. System has locked users. | F16: Passed | G16: 45914 | H16: TrungNVT | I16: Passed | J16: 45954 | K16: HuyNLQ | L16: Passed | M16: 45974 | N16: TrungNVT
A17: VIEW-USERS-006 | B17: View user list with no results | C17: 1. Login as admin successfully. 2. Navigate to "/admin/users" page. 3. Enter "NonExistentUser" in search box. 4. Press Enter key. 5. Check empty state. | D17: 1. "No users found" message is displayed. 2. Empty state is user-friendly. 3. Search box retains search term. 4. Pagination controls are hidden. 5. Clear search option is available. | E17: 1. Admin is logged in. | F17: Passed | G17: 45914 | H17: TrungNVT | I17: Passed | J17: 45954 | K17: HuyNLQ | L17: Passed | M17: 45974 | N17: TrungNVT
A18: VIEW-USERS-007 | B18: View user list with network error | C18: 1. Login as admin successfully. 2. Navigate to "/admin/users" page. 3. Disconnect network connection. 4. Try to refresh page or navigate. 5. Check error handling. | D18: 1. Error message "Network error" is displayed. 2. User list shows empty state. 3. Error message is user-friendly. 4. Retry option is available. 5. System handles error gracefully. | E18: 1. Admin is logged in. 2. Network can be disconnected. | F18: Passed | G18: 45914 | H18: TrungNVT | I18: Passed | J18: 45954 | K18: HuyNLQ | L18: Passed | M18: 45974 | N18: TrungNVT
A19: VIEW-USERS-08 | B19: View user list with backend unavailable | C19: 1. Login as admin successfully. 2. Navigate to "/admin/users" page. 3. Stop backend server. 4. Try to refresh page. 5. Check error handling. | D19: 1. Error message "Server unavailable" is displayed. 2. User list shows empty state. 3. Error message is clear and helpful. 4. Retry option is available. 5. System handles server error gracefully. | E19: 1. Admin is logged in. 2. Backend server can be stopped. | F19: Failed | G19: 45914 | H19: TrungNVT | I19: Passed | J19: 45954 | K19: HuyNLQ | L19: Passed | M19: 45974 | N19: TrungNVT | O19: Round 1: Wrong message displayed: "Failed to fetch users"
A20: VIEW-USERS-09 | B20: View user list with expired session | C20: 1. Login as admin successfully. 2. Wait for session to expire. 3. Navigate to "/admin/users" page. 4. Try to view user list. 5. Check system behavior. | D20: 1. User is redirected to login page. 2. Session expired message is displayed. 3. User list is not accessible. 4. User must login again. 5. Security is properly enforced. | E20: 1. Admin is logged in. 2. Session can expire. | F20: Passed | G20: 45914 | H20: TrungNVT | I20: Passed | J20: 45954 | K20: HuyNLQ | L20: Passed | M20: 45974 | N20: TrungNVT
A21: VIEW-USERS-010 | B21: View user list with non-admin user | C21: 1. Login with driver or parent account. 2. Try to navigate to "/admin/users" page. 3. Check system behavior. | D21: 1. Access is denied. 2. User is redirected to unauthorized page. 3. Error message "Access denied" is displayed. 4. Only admin can access user list. 5. Security is properly enforced. | E21: 1. Driver or Parent account exists. | F21: Passed | G21: 45914 | H21: TrungNVT | I21: Passed | J21: 45954 | K21: HuyNLQ | L21: Passed | M21: 45974 | N21: TrungNVT
A22: VIEW-USERS-0011 | B22: Sort users by name ascending | C22: 1. Login as admin successfully. 2. Navigate to "/admin/users" page. 3. Click "Name" sort. 4. Check sort order. | D22: 1. Users are sorted by first name A-Z. 2. Sort indicator shows ascending arrow. 3. All users on current page are sorted. 4. Sort persists across page changes. 5. Sort functionality works correctly. | E22: 1. Admin is logged in. 2. System has users with different first names. | F22: Passed | G22: 45914 | H22: TrungNVT | I22: Passed | J22: 45954 | K22: HuyNLQ | L22: Passed | M22: 45974 | N22: TrungNVT
A23: VIEW-USERS-012 | B23: Sort users by name descending | C23: 1. Login as admin successfully. 2. Navigate to "/admin/users" page. 3. Click "Name" sort. 4. Check sort order. | D23: 1. Users are sorted by first name Z-A. 2. Sort indicator shows descending arrow. 3. Sort order is reversed correctly. 4. All users are properly sorted. 5. Sort functionality works as expected. | E23: 1. Admin is logged in. 2. System has users with different first names. | F23: Passed | G23: 45914 | H23: TrungNVT | I23: Passed | J23: 45954 | K23: HuyNLQ | L23: Passed | M23: 45974 | N23: TrungNVT
A24: WEB-VIEW-USERS-015 | B24: Sort users by creation date ascending | C24: 1. Login as admin successfully. 2. Navigate to "/admin/users" page. 3. Click "Created At" sort. 4. Check sort order. | D24: 1. Users are sorted by creation date (oldest first). 2. Sort indicator shows ascending arrow. 3. All users on current page are sorted. 4. Sort persists across page changes. 5. Sort functionality works correctly. | E24: 1. Admin is logged in. 2. System has users created on different dates. | F24: Passed | G24: 45914 | H24: TrungNVT | I24: Passed | J24: 45954 | K24: HuyNLQ | L24: Passed | M24: 45974 | N24: TrungNVT
A25: WEB-VIEW-USERS-016 | B25: Sort users by creation date descending | C25: 1. Login as admin successfully. 2. Navigate to "/admin/users" page. 3. Click "Created At" sort. 4. Check sort order. | D25: 1. Users are sorted by creation date (newest first). 2. Sort indicator shows descending arrow. 3. Sort order is reversed correctly. 4. All users are properly sorted. 5. Sort functionality works as expected. | E25: 1. Admin is logged in. 2. System has users created on different dates. | F25: Passed | G25: 45914 | H25: TrungNVT | I25: Passed | J25: 45954 | K25: HuyNLQ | L25: Passed | M25: 45974 | N25: TrungNVT
A26: Create parent account
A27: CR-PR-001 | B27: Create parent with valid data. | C27: 1. Login as admin successfully. 2. Navigate to "/create-account" page. 3. Select "Parent Account" tab. 4. Fill all required fields. 5. Click "Create New Account" button. | D27: 1. Parent account is created successfully. 2. Success message is displayed. 3. Form is reset for next entry. | E27: Email is not already in use. | F27: Passed | G27: 45915 | H27: TrungNVT | I27: Passed | J27: 45954 | K27: HuyNLQ | L27: Passed | M27: 45974 | N27: TrungNVT
A28: CR-PR-002 | B28: Create parent with duplicate email | C28: 1. Login as admin successfully. 2. Navigate to "/create-account" page. 3. Select ""Parent Account"" tab. 4. Fill form with email that already exists in system. 5. Fill other required fields with valid data. 6. Click "Create New Account" button. | D28: 1. Error message "Email already exists" is displayed. 2. Account creation fails. 3. Form data is preserved for correction. 4. User can modify email and retry. | E28: Email already exists in system. | F28: N/A | G28: 45915 | H28: TrungNVT | I28: N/A | J28: 45954 | K28: HuyNLQ | L28: N/A | M28: 45974 | N28: TrungNVT
A29: CR-PR-002 | B29: Create parent with empty required fields | C29: 1. Login as admin successfully. 2. Navigate to "/create-account" page. 3. Select "Parent Account" tab. 4. Leave required fields empty. 5. Click "Create New Account" button. | D29: 1. Validation errors are displayed for empty fields: - "Email is required" - "First name is required" - "Last name is required" - "Phone number is required" - "Address is required" - "Gender is required" - "Date of birth is required" 2. Form submission is blocked. 3. User must fill required fields. | E29: 1. Admin is logged in | F29: Passed | G29: 45915 | H29: TrungNVT | I29: Passed | J29: 45954 | K29: HuyNLQ | L29: Passed | M29: 45974 | N29: TrungNVT
A30: CR-PR-003 | B30: Create parent with invalid email format | C30: 1. Login as admin successfully. 2. Navigate to "/create-account" page. 3. Select "Parent Account" tab. 4. Enter invalid email format (e.g., "invalid-email"). 5. Fill other required fields with valid data. 6. Click "Create New Account" button. | D30: 1. Validation error "Invalid email format" is displayed. 2. Account creation fails. 3. Form submission is blocked. 4. User must correct email format. | E30: 1. Admin is logged in. | F30: Passed | G30: 45915 | H30: TrungNVT | I30: Passed | J30: 45954 | K30: HuyNLQ | L30: Passed | M30: 45974 | N30: TrungNVT
A31: CR-PR-004 | B31: Create parent with invalid phone number | C31: 1. Login as admin successfully. 2. Navigate to "/create-account" page. 3. Select "Parent Account" tab. 4. Enter invalid phone number (e.g., "abc123"). 5. Fill other required fields with valid data. 6. Click "Create New Account" button. | D31: 1. Validation error "Invalid phone number format" is displayed. 2. Account creation fails. 3. Form submission is blocked. 4. User must correct phone number format. | E31: 1. Admin is logged in. | F31: Passed | G31: 45915 | H31: TrungNVT | I31: Passed | J31: 45954 | K31: HuyNLQ | L31: Passed | M31: 45974 | N31: TrungNVT
A32: CR-PR-005 | B32: Create parent with future date of birth | C32: 1. Login as admin successfully. 2. Navigate to "/create-account" page. 3. Select "Parent Account" tab. 4. Enter future date for date of birth. 5. Fill other required fields with valid data. 6. Click "Create New Account" button. | D32: 1. Validation error is displayed for invalid date. 2. Account creation fails. 3. Form submission is blocked. 4. User must enter valid past date. | E32: 1. Admin is logged in. | F32: Failed | G32: 45915 | H32: TrungNVT | I32: Passed | J32: 45954 | K32: HuyNLQ | L32: Passed | M32: 45974 | N32: TrungNVT | O32: Round 1: Select the date of birth in the future
A33: CR-PR-006 | B33: Create parent with very old date of birth | C33: 1. Login as admin successfully. 2. Navigate to "/create-account" page. 3. Select "Parent Account" tab. 4. Enter very old date (e.g., 1900-01-01). 5. Fill other required fields with valid data. 6. Click "Create New Account" button. | D33: 1. Validation error for invalid age is displayed. 2. Account creation fails. 3. Form submission is blocked. 4. User must enter reasonable birth date. | E33: 1. Admin is logged in. | F33: Failed | G33: 45915 | H33: TrungNVT | I33: Passed | J33: 45954 | K33: HuyNLQ | L33: Passed | M33: 45974 | N33: TrungNVT | O33: Round 1: Select very old date of birth
A34: CR-PR-007 | B34: Create parent with special characters in name | C34: 1. Login as admin successfully. 2. Navigate to "/create-account" page. 3. Select "Parent Account" tab. 4. Enter names with special characters (e.g., "JosÃ© MarÃ­a"). 5. Fill other required fields with valid data. 6. Click "Create New Account" button. | D34: 1. Parent account is created successfully. 2. Special characters are handled properly. 3. Success message is displayed. 4. Data is stored correctly in database. | E34: 1. Admin is logged in. 2. Email is not already in use. | F34: Failed | G34: 45915 | H34: TrungNVT | I34: Passed | J34: 45954 | K34: HuyNLQ | L34: Passed | M34: 45974 | N34: TrungNVT | O34: Round 1: Special characters can be entered for first name and last name.
A35: CR-PR-008 | B35: Create parent with long address | C35: 1. Login as admin successfully. 2. Navigate to "/create-account" page. 3. Select "Parent Account" tab. 4. Enter very long address (500+ characters). 5. Fill other required fields with valid data. 6. Click "Create New Account" button. | D35: 1. Parent account is created successfully. 2. Long address is handled properly. 3. Success message is displayed. 4. Data is stored correctly in database. | E35: 1. Admin is logged in. 2. Email is not already in use. | F35: Failed | G35: 45915 | H35: TrungNVT | I35: Passed | J35: 45954 | K35: HuyNLQ | L35: Passed | M35: 45974 | N35: TrungNVT | O35: Round 1: No character limit for addresses
A36: CR-PR-009 | B36: Create parent with backend unavailable | C36: 1. Login as admin successfully. 2. Navigate to "/create-account" page. 3. Select "Parent Account" tab. 4. Fill form with valid data. 5. Stop backend server. 6. Click "Create New Account" button. | D36: 1. Error message "Server unavailable" is displayed. 2. Account creation fails. 3. Form data is preserved. 4. User can retry when backend is restored. | E36: 1. Admin is logged in. 2. Backend server can be stopped. | F36: Failed | G36: 45915 | H36: TrungNVT | I36: Passed | J36: 45954 | K36: HuyNLQ | L36: Passed | M36: 45974 | N36: TrungNVT | O36: Round 1: Wrong message displayed: "Parent creation failed. Data was not saved to the database."
A37: CR-PR-010 | B37: Create parent with expired session | C37: 1. Login as admin successfully. 2. Wait for session to expire. 3. Navigate to "/create-account" page. 4. Select "Parent Account" tab. 5. Fill form with valid data. 6. Click "Create New Account" button. | D37: 1. User is redirected to login page. 2. Account creation fails. 3. Session expired message is displayed. 4. User must login again. | E37: 1. Admin is logged in. 2. Session can expire. | F37: Passed | G37: 45915 | H37: TrungNVT | I37: Passed | J37: 45954 | K37: HuyNLQ | L37: Passed | M37: 45974 | N37: TrungNVT
A38: CR-PR-011 | B38: Create parent with browser refresh during submission | C38: 1. Login as admin successfully. 2. Navigate to "/create-account" page. 3. Select "Parent Account" tab. 4. Fill form with valid data. 5. Click "Create New Account" button. 6. Refresh browser immediately after clicking. | D38: 1. Account creation may succeed or fail. 2. No duplicate accounts are created. 3. System handles refresh gracefully. 4. User can verify account status. | E38: 1. Admin is logged in. | F38: Passed | G38: 45915 | H38: TrungNVT | I38: Passed | J38: 45954 | K38: HuyNLQ | L38: Passed | M38: 45974 | N38: TrungNVT
A39: CR-PR-012 | B39: Create parent with multiple rapid submissions | C39: 1. Login as admin successfully. 2. Navigate to "/create-account" page. 3. Select "Parent Account" tab. 4. Fill form with valid data. 5. Click "Create New Account" button multiple times rapidly. | D39: 1. Only one account is created. 2. Duplicate submissions are prevented. 3. Success message is displayed once. 4. Button is disabled during processing. | E39: 1. Admin is logged in. | F39: Passed | G39: 45915 | H39: TrungNVT | I39: Passed | J39: 45954 | K39: HuyNLQ | L39: Passed | M39: 45974 | N39: TrungNVT
A40: CR-PR-013 | B40: Create parent with different gender options | C40: 1. Login as admin successfully. 2. Navigate to "/create-account" page. 3. Select "Parent Account" tab. 4. Test each gender option: - Male - Female - Other 5. Fill other required fields with valid data. 6. Click "Create New Account" button for each. | D40: 1. All gender options work correctly. 2. Accounts are created successfully for each gender. 3. Gender data is stored correctly in database. 4. Success messages are displayed. | E40: 1. Admin is logged in. 2. Different emails for each test. | F40: Passed | G40: 45915 | H40: TrungNVT | I40: Passed | J40: 45954 | K40: HuyNLQ | L40: N/A | M40: 45974 | N40: TrungNVT
A41: CR-PR-014 | B41: Create parent with minimum age validation | C41: 1. Login as admin successfully. 2. Navigate to "/create-account" page. 3. Select "Parent Account" tab. 4. Enter date of birth making parent exactly 18 years old. 5. Fill other required fields with valid data. 6. Click "Create New Account" button. | D41: 1. Parent account is created successfully. 2. Age validation passes for 18-year-old. 3. Success message is displayed. 4. Account is created without issues. | E41: 1. Admin is logged in. 2. Email is not already in use. | F41: Passed | G41: 45915 | H41: TrungNVT | I41: Passed | J41: 45954 | K41: HuyNLQ | L41: Passed | M41: 45974 | N41: TrungNVT
A42: CR-PR-015 | B42: Create parent with maximum age validation | C42: 1. Login as admin successfully. 2. Navigate to "/create-account" page. 3. Select "Parent Account" tab. 4. Enter date of birth making parent 100 years old. 5. Fill other required fields with valid data. 6. Click "Create New Account" button. | D42: 1. Validation error for maximum age is displayed. 2. Account creation fails. 3. Form submission is blocked. 4. User must enter reasonable age. | E42: 1. Admin is logged in. | F42: Failed | G42: 45915 | H42: TrungNVT | I42: Passed | J42: 45954 | K42: HuyNLQ | L42: Passed | M42: 45974 | N42: TrungNVT | O42: Round 1: No maximum age limit
...

Sheet Student Management
A2: Feature | B2: Student management | R2: Passed
A3: Test requirement | B3: Verifies the complete student management flow—including creating, viewing, editing, and deactivating student records—covering input validation, relationship consistency (class, parent, bus assignments), permission checks, data integrity, and graceful error handling. | R3: Failed
A4: Number of TCs | B4: =COUNTA(A12:A916)-8 -> 44 | R4: Pending
A5: Testing Round | B5: Passed | C5: Failed | D5: Pending | E5: N/A | R5: N/A
A6: Round 1 | B6: =COUNTIF($F10:$F914,B5) -> 39 | C6: =COUNTIF($F10:$F914,C5) -> 4 | D6: =COUNTIF($F10:$F914,D5) -> 0 | E6: =COUNTIF($F10:$F914,E5) -> 1
A7: Round 2 | B7: =COUNTIF($I10:$I914,B5) -> 39 | C7: =COUNTIF($I10:$I914,C5) -> 3 | D7: =COUNTIF($F10:$F914,D5) -> 0 | E7: =COUNTIF($F10:$F914,E5) -> 1
A8: Round 3 | B8: =COUNTIF($L10:$L914,B5) -> 41 | C8: =COUNTIF($L10:$L914,C5) -> 0 | D8: =COUNTIF($F10:$F914,D5) -> 0 | E8: =COUNTIF($F10:$F914,E5) -> 1
A10: Test Case ID | B10: Test Case Description | C10: Test Case Procedure | D10: Expected Results | E10: Pre-conditions | F10: Round 1 | G10: Test date | H10: Tester | I10: Round 2 | J10: Test date | K10: Tester | L10: Round 3 | M10: Test date | N10: Tester | O10: Note
A11: Add Student
A12: STU-001 | B12: Verify that a student can be successfully created with valid data by an admin user. | C12: 1.Send POST request to /api/Student with valid student data 2.Include admin authorization token in headers 3.Verify response status and data | D12: 1.Status Code: 201 Created 2.Response contains student data with generated ID 3.Student status is set to "Available" 4.Student is created in database | E12: 1. Admin user is authenticated 2. Database is accessible | F12: Passed | G12: 45914 | H12: KhoiVN | I12: Passed | J12: 45954 | K12: NguyetNTT | L12: Passed | M12: 45974 | N12: KhoiVN
A13: STU-002 | B13: Verify that creating a student fails when required fields are missing. | C13: 1. Send POST request to /api/Student with missing firstName 2. Include admin authorization token in headers 3. Verify error response | D13: 1. Status Code: 400 Bad Request 2. Error message indicates missing required field 3. No student is created in database | E13: 1. Admin user is authenticated 2. Database is accessible | F13: Failed | G13: 45914 | H13: KhoiVN | I13: Failed | J13: 45954 | K13: NguyetNTT | L13: Passed | M13: 45974 | N13: KhoiVN | O13: When both parentId and parentEmail are provided, The new parentEmail override the existing email in user table. Need to be clarified here.
A14: STU-003 | B14: Verify that non-admin users cannot create students. | C14: 1.Send POST request to /api/Student with valid data 2.Include parent authorization token in headers 3.Verify access denied response | D14: 1. Status Code: 403 Forbidden 2. Access denied error 3. No student is created in database | E14: 1. Parent user is authenticated (non-admin) 2. Database is accessible | F14: Passed | G14: 45914 | H14: KhoiVN | I14: Passed | J14: 45954 | K14: NguyetNTT | L14: Passed | M14: 45974 | N14: KhoiVN
A15: STU-004 | B15: Verify that students can be imported from a valid Excel file. | C15: 1. Send POST request to /api/Student/import with Excel file 2. Include admin authorization token in headers 3. Verify response status and import results | D15: 1. Status Code: 200 OK 2. Response contains import statistics 3. Successful students are created in database 4. Failed students are reported with reasons | E15: 1. Admin user is authenticated 2. Valid Excel file with student data exists 3. Database is accessible | F15: Passed | G15: 45914 | H15: KhoiVN | I15: Failed | J15: 45954 | K15: NguyetNTT | L15: Passed | M15: 45974 | N15: KhoiVN
A16: STU-005 | B16: Verify that importing fails with invalid file format. | C16: 1. Send POST request to /api/Student/import with .csv file 2. Include admin authorization token in headers 3. Verify error response | D16: 1. Status Code: 400 Bad Request 2. Error message indicates only .xlsx files are supported 3. No students are imported | E16: 1. Admin user is authenticated 2. Invalid file format exists 3. Database is accessible | F16: Passed | G16: 45914 | H16: KhoiVN | I16: Passed | J16: 45954 | K16: NguyetNTT | L16: Passed | M16: 45974 | N16: KhoiVN
A17: STU-006 | B17: Verify that creating a student fails when ParentEmail format is invalid. | C17: 1. Send POST request to /api/Student with invalid email format 2. Include admin authorization token in headers 3.Verify error response | D17: 1. Status Code: 400 Bad Request 2. Error message indicates invalid email format 3. No student is created in database | E17: 1. Admin user is authenticated 2. Database is accessible | F17: Passed | G17: 45914 | H17: KhoiVN | I17: Passed | J17: 45954 | K17: NguyetNTT | L17: Passed | M17: 45974 | N17: KhoiVN
A18: STU-007 | B18: Verify that creating a student fails when firstName exceeds 50 characters. | C18: 1. Send POST request to /api/Student with firstName longer than 50 characters 2. Include admin authorization token in headers 3. Verify error response | D18: 1. Status Code: 400 Bad Request 2. Error message indicates firstName cannot exceed 50 characters 3. No student is created in database | E18: 1. Admin user is authenticated 2. Database is accessible | F18: Failed | G18: 45914 | H18: KhoiVN | I18: Passed | J18: 45954 | K18: NguyetNTT | L18: Passed | M18: 45974 | N18: KhoiVN | O18: API passed but No validation in UI
A19: View Student
A20: STU-008 | B20: Verify that parent can retrieve their own child's data but not other children. | C20: 1. Send GET request to /api/Student/{own-child-id} 2. Include parent authorization token in headers 3. Verify successful access 4. Send GET request to /api/Student/{other-child-id} 5. Verify access denied | D20: 1. Own child: Status Code 200 OK with student data 2. Other child: Status Code 403 Forbidden with access denied | E20: 1. Parent user is authenticated 2. Student belongs to the authenticated parent 3. Another student belongs to different parent 4. Database is accessible | F20: N/A | G20: 45914 | H20: KhoiVN | I20: N/A | J20: 45954 | K20: NguyetNTT | L20: N/A | M20: 45974 | N20: KhoiVN
A21: STU-009 | B21: Verify that admin can retrieve list of students with filters applied | C21: 1. Send GET request to /api/Student 2. Provide proper filters in the url params 3. Verify returned data | D21: 1. Correct list of students is returned | E21: 1. Admin user is authenticated 2. Database is accessible | F21: Passed | G21: 45914 | H21: KhoiVN | I21: Passed | J21: 45954 | K21: NguyetNTT | L21: Passed | M21: 45974 | N21: KhoiVN
A22: STU-010 | B22: Verify that students can be exported to Excel by an admin user. | C22: 1. Send GET request to /api/Student/export 2. Include admin authorization token in headers 3. Verify response status and file content | D22: 1. Status Code: 200 OK 2. Response contains Excel file with proper content type 3. File includes all student data with correct headers 4. File is downloadable as "Students.xlsx" | E22: 1. Admin user is authenticated 2. Database is accessible | F22: Passed | G22: 45914 | H22: KhoiVN | I22: Passed | J22: 45954 | K22: NguyetNTT | L22: Passed | M22: 45974 | N22: KhoiVN
A23: STU-011 | B23: Verify that getting students by invalid status fails. | C23: 1. Send GET request to /api/Student/status/99 (invalid status) 2. Include admin authorization token in headers 3. Verify error response | D23: 1. Status Code: 400 Bad Request 2. Error message indicates invalid status value with valid options 3. No data is returned | E23: 1. Admin user is authenticated 2. Database is accessible | F23: Passed | G23: 45914 | H23: KhoiVN | I23: Failed | J23: 45954 | K23: NguyetNTT | L23: N/A | M23: 45974 | N23: KhoiVN
A24: STU-012 | B24: Verify that a parent cannot access a student who has no parent assigned (ParentId is null). | C24: 1. Create a student with ParentId = null (no parent assigned) 2. Send GET request to /api/Student/{student-id} with parent authorization token 3. Verify access denied response | D24: 1. Status Code: 403 Forbidden 2. Access denied error 3. Student data is not returned | E24: 1. Driver user is authenticated 2. Students and parents exist, students are not linked to parents 3. Database is accessible | F24: Passed | G24: 45914 | H24: KhoiVN | I24: Passed | J24: 45954 | K24: NguyetNTT | L24: Passed | M24: 45974 | N24: KhoiVN
A25: STU-013 | B25: Verify that a driver cannot access any student data. | C25: 1. Send GET request to /api/Student/{student-id} with driver authorization token 2. Verify access denied response 3. Send GET request to /api/Student/parent/{parent-id} with driver authorization token 4. Verify access denied response | D25: 1. Both requests return Status Code: 403 Forbidden 2. Access denied error for both endpoints 3. No student data is returned | E25: 1. Driver user is authenticated 2. Students exist 3. Database is accessible | F25: Passed | G25: 45914 | H25: KhoiVN | I25: N/A | J25: 45954 | K25: NguyetNTT | L25: N/A | M25: 45974 | N25: KhoiVN
A26: Update
A27: STU-014 | B27: Verify that a student can be successfully updated with valid data by an admin user. | C27: 1. Send PUT request to /api/Student/{id} with updated data 2. Include admin authorization token in headers 3. Verify response status and updated data | D27: 1. Status Code: 200 OK 2. Response contains updated student data 3. Student data is updated in database | E27: 1. Admin user is authenticated 2. Student exists in the system 3. Database is accessible | F27: Failed | G27: 45914 | H27: KhoiVN | I27: Passed | J27: 45954 | K27: NguyetNTT | L27: Passed | M27: 45974 | N27: KhoiVN | O27: In UI: display phone number instead of email Required email, while email is optional when creating, needs to be clarified
A28: STU-015 | B28: Verify that a student can be successfully activated by an admin. | C28: 1. Send POST request to /api/Student/{id}/activate 2. Include admin authorization token in headers 3. Verify response status and updated student data | D28: 1. Status Code: 200 OK 2. Response contains updated student data 3. Student status is changed to Active 4. ActivatedAt timestamp is set | E28: 1. Admin user is authenticated 2. Student exists in the system with Available status 3. Database is accessible | F28: Passed | G28: 45914 | H28: KhoiVN | I28: Passed | J28: 45954 | K28: NguyetNTT | L28: Passed | M28: 45974 | N28: KhoiVN
A29: STU-016 | B29: Verify that a student can be successfully deactivated with reason by an admin. | C29: 1. Send POST request to /api/Student/{id}/deactivate with reason 2. Include admin authorization token in headers 3. Verify response status and updated student data | D29: 1. Status Code: 200 OK 2. Response contains updated student data 3. Student status is changed to Inactive 4. DeactivatedAt timestamp is set 5. DeactivationReason is stored | E29: 1. Admin user is authenticated 2. Student exists in the system with Active status 3. Database is accessible | F29: Passed | G29: 45914 | H29: KhoiVN | I29: Passed | J29: 45954 | K29: NguyetNTT | L29: Passed | M29: 45974 | N29: KhoiVN
A30: STU-017 | B30: Verify that students can be filtered by status. | C30: 1. Send GET request to /api/Student/status/{status} 2. Include admin authorization token in headers 3. Verify response status and filtered student list | D30: 1. Status Code: 200 OK 2. Response contains array of students with Active status only 3. All returned students have status = Active | E30: 1. Admin user is authenticated 2. Students with different statuses exist in the system 3. Database is accessible | F30: Passed | G30: 45914 | H30: KhoiVN | I30: Passed | J30: 45954 | K30: NguyetNTT | L30: Passed | M30: 45974 | N30: KhoiVN
A31: STU-018 | B31: Verify that deactivating a student fails when reason is missing. | C31: 1. Send POST request to /api/Student/{id}/deactivate with empty request body 2. Include admin authorization token in headers 3. Verify error response | D31: 1. Status Code: 400 Bad Request 2. Error message indicates deactivation reason is required 3. Student status remains unchanged | E31: 1. Admin user is authenticated 2. Students with active statuses exist in the system 3. Database is accessible | F31: Passed | G31: 45914 | H31: KhoiVN | I31: Passed | J31: 45954 | K31: NguyetNTT | L31: Passed | M31: 45974 | N31: KhoiVN | O31: Only alert in UI, better have a modal
A32: STU-019 | B32: Verify that activating a non-existent student fails. | C32: 1. Send POST request to /api/Student/{non-existent-id}/activate 2. Include admin authorization token in headers 3. Verify error response | D32: 1. Status Code: 404 Not Found 2. Error message indicates student not found 3. No changes are made to database | E32: 1. Admin user is authenticated 2. Students with such id does not exist in the system 3. Database is accessible | F32: Passed | G32: 45914 | H32: KhoiVN | I32: Passed | J32: 45954 | K32: NguyetNTT | L32: Passed | M32: 45974 | N32: KhoiVN
A33: Update
A34: STU-020 | B34: Verify that a student can be successfully updated with valid data by an admin user. | C34: 1. Send PUT request to /api/Student/{id} with updated data 2. Include admin authorization token in headers 3. Verify response status and updated data | D34: 1. Status Code: 200 OK 2. Response contains updated student data 3. Student data is updated in database | E34: 1. Admin user is authenticated 2. Student exists in the system 3. Database is accessible | F34: Failed | G34: 45914 | H34: KhoiVN | I34: Passed | J34: 45954 | K34: NguyetNTT | L34: Passed | M34: 45974 | N34: KhoiVN | O34: In UI: display phone number instead of email Required email, while email is optional when creating, needs to be clarified
A35: STU-021 | B35: Verify that a student can be successfully activated by an admin. | C35: 1. Send POST request to /api/Student/{id}/activate 2. Include admin authorization token in headers 3. Verify response status and updated student data | D35: 1. Status Code: 200 OK 2. Response contains updated student data 3. Student status is changed to Active 4. ActivatedAt timestamp is set | E35: 1. Admin user is authenticated 2. Student exists in the system with Available status 3. Database is accessible | F35: Passed | G35: 45914 | H35: KhoiVN | I35: Passed | J35: 45954 | K35: NguyetNTT | L35: Passed | M35: 45974 | N35: KhoiVN
A36: STU-022 | B36: Verify that a student can be successfully deactivated with reason by an admin. | C36: 1. Send POST request to /api/Student/{id}/deactivate with reason 2. Include admin authorization token in headers 3. Verify response status and updated student data | D36: 1. Status Code: 200 OK 2. Response contains updated student data 3. Student status is changed to Inactive 4. DeactivatedAt timestamp is set 5. DeactivationReason is stored | E36: 1. Admin user is authenticated 2. Student exists in the system with Active status 3. Database is accessible | F36: Passed | G36: 45914 | H36: KhoiVN | I36: Passed | J36: 45954 | K36: NguyetNTT | L36: Passed | M36: 45974 | N36: KhoiVN
A37: STU-023 | B37: Verify that students can be filtered by status. | C37: 1. Send GET request to /api/Student/status/{status} 2. Include admin authorization token in headers 3. Verify response status and filtered student list | D37: 1. Status Code: 200 OK 2. Response contains array of students with Active status only 3. All returned students have status = Active | E37: 1. Admin user is authenticated 2. Students with different statuses exist in the system 3. Database is accessible | F37: Passed | G37: 45914 | H37: KhoiVN | I37: Passed | J37: 45954 | K37: NguyetNTT | L37: Passed | M37: 45974 | N37: KhoiVN
A38: STU-024 | B38: Verify that deactivating a student fails when reason is missing. | C38: 1. Send POST request to /api/Student/{id}/deactivate with empty request body 2. Include admin authorization token in headers 3. Verify error response | D38: 1. Status Code: 400 Bad Request 2. Error message indicates deactivation reason is required 3. Student status remains unchanged | E38: 1. Admin user is authenticated 2. Students with active statuses exist in the system 3. Database is accessible | F38: Passed | G38: 45914 | H38: KhoiVN | I38: Passed | J38: 45954 | K38: NguyetNTT | L38: Passed | M38: 45974 | N38: KhoiVN | O38: Only alert in UI, better have a modal
A39: STU-025 | B39: Verify that activating a non-existent student fails. | C39: 1. Send POST request to /api/Student/{non-existent-id}/activate 2. Include admin authorization token in headers 3. Verify error response | D39: 1. Status Code: 404 Not Found 2. Error message indicates student not found 3. No changes are made to database | E39: 1. Admin user is authenticated 2. Students with such id does not exist in the system 3. Database is accessible | F39: Passed | G39: 45914 | H39: KhoiVN | I39: Passed | J39: 45954 | K39: NguyetNTT | L39: Passed | M39: 45974 | N39: KhoiVN
A40: STUDENT_CRUD
A41: STU-026 | B41: Test deleting student (Soft Delete) | C41: 1. Login as Admin 2. Call DELETE /api/student/{id} 3. Submit | D41: 1. Returns 200 OK 2. Student IsDeleted = true 3. Student removed from active lists 4. Historical data preserved | E41: 1. Active student exists | F41: Passed | G41: 45914 | H41: KhoiVN | I41: Passed | J41: 45954 | K41: NguyetNTT | L41: Passed | M41: 45974 | N41: KhoiVN | O41: In UI: display phone number instead of email Required email, while email is optional when creating, needs to be clarified
A42: STU-027 | B42: Test importing students from Excel | C42: 1. Login as Admin 2. Call POST /api/student/import 3. Upload valid .xlsx file 4. Submit | D42: 1. Returns 200 OK 2. Returns count of successful/failed imports 3. Students created in database 4. Duplicate emails handled gracefully | E42: 1. Valid Excel file | F42: Passed | G42: 45914 | H42: KhoiVN | I42: Passed | J42: 45954 | K42: NguyetNTT | L42: Passed | M42: 45974 | N42: KhoiVN
...

Sheet School System Configuration
A2: Feature | B2: School System Configuration | R2: Passed
A3: Test requirement | B3: Verifies the full configuration flow for school-wide system settings—including updating school information, location, branding, pricing, operational rules, and system parameters—covering input validation, permission control, dependency checks, and consistent system-wide impact. | R3: Failed
A4: Number of TCs | B4: =COUNTA(A12:A896)-6 -> 26 | R4: Pending
A5: Testing Round | B5: Passed | C5: Failed | D5: Pending | E5: N/A | R5: N/A
A6: Round 1 | B6: =COUNTIF($F10:$F894,B5) -> 23 | C6: =COUNTIF($F10:$F894,C5) -> 2 | D6: =COUNTIF($F10:$F894,D5) -> 1 | E6: =COUNTIF($F10:$F894,E5) -> 0
A7: Round 2 | B7: =COUNTIF($I10:$I894,B5) -> 23 | C7: =COUNTIF($I10:$I894,C5) -> 2 | D7: =COUNTIF($F10:$F894,D5) -> 1 | E7: =COUNTIF($F10:$F894,E5) -> 0
A8: Round 3 | B8: =COUNTIF($L10:$L894,B5) -> 23 | C8: =COUNTIF($L10:$L894,C5) -> 0 | D8: =COUNTIF($F10:$F894,D5) -> 1 | E8: =COUNTIF($F10:$F894,E5) -> 0
A10: Test Case ID | B10: Test Case Description | C10: Test Case Procedure | D10: Expected Results | E10: Pre-conditions | F10: Round 1 | G10: Test date | H10: Tester | I10: Round 2 | J10: Test date | K10: Tester | L10: Round 3 | M10: Test date | N10: Tester | O10: Note
A11: PARENT_NOTIFICATIONS
A12: CONF-001 | B12: Test creating initial school information | C12: 1. Login as Admin 2. Call POST /api/school 3. Body: {name, address, email, phone} 4. Submit | D12: 1. Returns 201 Created 2. School info saved 3. IsActive = true by default | E12: 1. No school info exists | F12: Passed | G12: 45914 | H12: HuyNLQ | I12: Passed | J12: 45954 | K12: HuyNLQ | L12: Passed | M12: 45974 | N12: KhoiVN
A13: CONF-002 | B13: Test preventing duplicate school creation | C13: 1. School info already exists 2. Call POST /api/school again 3. Submit | D13: 1. Returns 409 Conflict 2. Error "School already exists" 3. System enforces singleton school record | E13: 1. School info exists | F13: Passed | G13: 45914 | H13: HuyNLQ | I13: Passed | J13: 45954 | K13: HuyNLQ | L13: Pending | M13: 45974 | N13: KhoiVN
A14: CONF-003 | B14: Test updating school information | C14: 1. Login as Admin 2. Call PUT /api/school/{id} 3. Update name and contact info 4. Submit | D14: 1. Returns 200 OK 2. Data updated in database 3. UpdatedAt timestamp refreshed | E14: 1. School info exists | F14: Passed | G14: 45914 | H14: HuyNLQ | I14: Passed | J14: 45954 | K14: HuyNLQ | L14: Passed | M14: 45974 | N14: KhoiVN
A15: CONF-004 | B15: Test public access to school info | C15: 1. No login (Anonymous) 2. Call GET /api/school 3. Check response | D15: 1. Returns 200 OK 2. Public info (name, address, contact) returned 3. Internal notes NOT returned | E15: 1. School info exists | F15: Passed | G15: 45914 | H15: HuyNLQ | I15: Passed | J15: 45954 | K15: HuyNLQ | L15: Passed | M15: 45974 | N15: KhoiVN
A16: CONF-005 | B16: Test admin access to full school info | C16: 1. Login as Admin 2. Call GET /api/school/admin 3. Check response | D16: 1. Returns 200 OK 2. Includes InternalNotes, IsPublished status 3. Full details available | E16: 1. Admin account | F16: Failed | G16: 45914 | H16: HuyNLQ | I16: Passed | J16: 45954 | K16: HuyNLQ | L16: Passed | M16: 45974 | N16: KhoiVN
A17: LOCATION_IMAGES
A18: CONF-006 | B18: Test updating school location (Map Picker) | C18: 1. Login as Admin 2. Call PUT /api/school/{id}/location 3. Body: {lat, long, fullAddress, displayAddress} 4. Submit | D18: 1. Returns 200 OK 2. Coordinates updated 3. Spatial data (Geog point) updated correctly for map queries | E18: 1. Valid coordinates | F18: Passed | G18: 45914 | H18: HuyNLQ | I18: Failed | J18: 45954 | K18: HuyNLQ | L18: Passed | M18: 45974 | N18: KhoiVN
A19: CONF-007 | B19: Test retrieving school images | C19: 1. Login as Admin 2. Call GET /api/school/images 3. Check response | D19: 1. Returns list of active images 2. Filtered by types: Logo, Banner, Gallery, etc. 3. Includes file URLs and metadata | E19: 1. Images uploaded | F19: Failed | G19: 45914 | H19: HuyNLQ | I19: Passed | J19: 45954 | K19: HuyNLQ | L19: Passed | M19: 45974 | N19: KhoiVN
A20: CONF-008 | B20: Test updating location with invalid coordinates | C20: 1. Call PUT /api/school/{id}/location 2. Body: {lat: 95.0, long: 200.0} 3. Submit | D20: 1. Returns 400 Bad Request 2. Validation error for coordinate range | E20: None | F20: Passed | G20: 45914 | H20: HuyNLQ | I20: Passed | J20: 45954 | K20: HuyNLQ | L20: Pending | M20: 45974 | N20: KhoiVN
A21: UNIT_PRICE_CRUD
A22: CONF-009 | B22: Test creating new unit price | C22: 1. Login as Admin 2. Call POST /api/unitprice 3. Body: {name, pricePerKm: 10000, effectiveFrom: tomorrow} 4. Submit | D22: 1. Returns 201 Created 2. Unit price saved 3. CreatedByAdmin info recorded | E22: 1. No overlapping prices | F22: Passed | G22: 45914 | H22: HuyNLQ | I22: Passed | J22: 45954 | K22: HuyNLQ | L22: Passed | M22: 45974 | N22: KhoiVN
A23: CONF-010 | B23: Test updating unit price details | C23: 1. Call PUT /api/unitprice/{id} 2. Update price and description 3. Submit | D23: 1. Returns 200 OK 2. Price updated 3. Effective dates updated if changed | E23: 1. Unit price exists | F23: Passed | G23: 45914 | H23: HuyNLQ | I23: Failed | J23: 45954 | K23: HuyNLQ | L23: Passed | M23: 45974 | N23: KhoiVN
A24: CONF-011 | B24: Test soft deleting unit price | C24: 1. Call DELETE /api/unitprice/{id} 2. Submi | D24: 1. Returns 204 No Content 2. IsDeleted = true 3. IsActive = false 4. EffectiveTo set to now | E24: 1. Active unit price | F24: Passed | G24: 45914 | H24: HuyNLQ | I24: Passed | J24: 45954 | K24: HuyNLQ | L24: Passed | M24: 45974 | N24: KhoiVN
A25: CONF-012 | B25: Test retrieving current effective price | C25: 1. Call GET /api/unitprice/current-effective 2. Check response | D25: 1. Returns single price config 2. Price is active AND (EffectiveFrom <= Now <= EffectiveTo) 3. Used for fee calculation | E25: 1. Active effective price exists | F25: Passed | G25: 45914 | H25: HuyNLQ | I25: Passed | J25: 45954 | K25: HuyNLQ | L25: Passed | M25: 45974 | N25: KhoiVN
A26: CONF-013 | B26: Test retrieving all unit prices (including deleted) | C26: 1. Call GET /api/unitprice/all-including-deleted 2. Check list | D26: 1. Returns active, inactive, and deleted prices 2. Useful for audit trail | E26: 1. Deleted prices exist | F26: Passed | G26: 45914 | H26: HuyNLQ | I26: Passed | J26: 45954 | K26: HuyNLQ | L26: Passed | M26: 45974 | N26: KhoiVN
A27: PRICE_VALIDATION
A28: CONF-014 | B28: Test preventing overlapping price ranges (Create) | C28: 1. Existing price: Jan 1 - Jan 31 2. Create new price: Jan 15 - Feb 15 3. Submit | D28: 1. Returns 400 Bad Request or 500 (InvalidOperation) 2. Error "Cannot create new UnitPrice in this time range" 3. Overlap | E28: 1. Active price exists | F28: Passed | G28: 45914 | H28: HuyNLQ | I28: Passed | J28: 45954 | K28: HuyNLQ | L28: Passed | M28: 45974 | N28: KhoiVN
A29: CONF-015 | B29: Test preventing overlapping price ranges (Update) | C29: 1. Price A: Jan 1 - Jan 31 2. Price B: Feb 1 - Feb 28 3. Update Price B to start Jan 20 4. Submit | D29: 1. Returns 400/500 2. Error "Cannot update UnitPrice in this time range" 3. Overlap detected | E29: 1. Two active prices | F29: Passed | G29: 45914 | H29: HuyNLQ | I29: Passed | J29: 45954 | K29: HuyNLQ | L29: Passed | M29: 45974 | N29: KhoiVN
A30: CONF-016 | B30: Test creating price with open-ended EffectiveTo | C30: 1. Create price: EffectiveFrom = Tomorrow, EffectiveTo = null 2. Submit | D30: 1. Returns 201 Created 2. Price valid indefinitely from start date | E30: 1. No future prices exist | F30: Passed | G30: 45914 | H30: HuyNLQ | I30: Passed | J30: 45954 | K30: HuyNLQ | L30: Passed | M30: 45974 | N30: KhoiVN
A31: CONF-017 | B31: Test overlap with open-ended price | C31: 1. Existing price: Jan 1 - null (forever) 2. Create new price: Feb 1 - Feb 28 3. Submit | D31: 1. Returns Error 2. Overlap detected with open-ended existing price | E31: 1. Open-ended price exists | F31: Passed | G31: 45914 | H31: HuyNLQ | I31: Passed | J31: 45954 | K31: HuyNLQ | L31: Passed | M31: 45974 | N31: KhoiVN
A32: CONF-018 | B32: Test creating price in gap period | C32: 1. Price A: Jan 1 - Jan 15 2. Price B: Feb 1 - Feb 15 3. Create Price C: Jan 16 - Jan 31 4. Submit | D32: 1. Returns 201 Created 2. No overlap detected 3. Gap filled successfully | E32: 1. Gap exists between prices | F32: Passed | G32: 45914 | H32: HuyNLQ | I32: Passed | J32: 45954 | K32: HuyNLQ | L32: Passed | M32: 45974 | N32: KhoiVN
A33: Update school's location
A34: CONF-019 | B34: Test prevent update with invalid location | C34: 1. Existing location: long 111.2 lat 122.3 2. New location: long 222.3 lat 333.4 3. Submit | D34: 1. Returns 400 Bad Request or 500 (InvalidOperation) 2. Error "Cannot update with invalid location" 3. rejected | E34: 1. Location exist | F34: Passed | G34: 45914 | H34: HuyNLQ | I34: Passed | J34: 45954 | K34: HuyNLQ | L34: Passed | M34: 45974 | N34: KhoiVN
A35: CONF-020 | B35: Test prevent other user except admin can update | C35: 1. Login as parent 2. attempt to access the endpoint school/location/update | D35: 1. Returns 400/500 2. Error "You're not allowed to access this" 3. Rejected | E35: 1. login as parent | F35: Passed | G35: 45914 | H35: HuyNLQ | I35: Passed | J35: 45954 | K35: HuyNLQ | L35: Passed | M35: 45974 | N35: KhoiVN
A36: CONF-021 | B36: Test prevent updating during active trip | C36: 1. Login as admin 2. Attempt to update the locaiton during active trip | D36: 1. Returns badrequest 400 2. Location not updated during trip | E36: 1. Trip and location exist | F36: Passed | G36: 45914 | H36: HuyNLQ | I36: Passed | J36: 45954 | K36: HuyNLQ | L36: Passed | M36: 45974 | N36: KhoiVN
A37: Update school's information
A38: CONF-022 | B38: Test prevent update with invalid information | C38: 1. Schoolname: name with unallowed chars 2. SchoolImage: unsupported file type 3. Submit | D38: 1. Returns 400 Bad Request 2. Error "Please try again with valid information" 3. rejected | E38: 1. School exist | F38: Passed | G38: 45914 | H38: HuyNLQ | I38: Passed | J38: 45954 | K38: HuyNLQ | L38: Passed | M38: 45974 | N38: KhoiVN
A39: CONF-023 | B39: Test prevent other user except admin can update | C39: 1. Login as parent 2. attempt to access the endpoint school/information/update | D39: 1. Returns 400/500 2. Error "You're not allowed to access this" 3. Rejected | E39: 1. login as parent | F39: Passed | G39: 45914 | H39: HuyNLQ | I39: Passed | J39: 45954 | K39: HuyNLQ | L39: Passed | M39: 45974 | N39: KhoiVN
A40: CONF-024 | B40: Test updating with valid data | C40: 1. Login as admin 2. Valid image: png 3. Valid name: "FPT School" | D40: 1. Returns 203 updated 2. School info updated successfully | E40: 1. School exist | F40: Passed | G40: 45914 | H40: HuyNLQ | I40: Passed | J40: 45954 | K40: HuyNLQ | L40: Passed | M40: 45974 | N40: KhoiVN
A41: View school's information
A42: CONF-025 | B42: Login to view school information | C42: 1. Login as admin 2. Navigate about school page 3. Waiting for data to retrieve | D42: 1. Returns 200 success 2. School information is displayed correctly | E42: 1. School exist | F42: Passed | G42: 45914 | H42: HuyNLQ | I42: Passed | J42: 45954 | K42: HuyNLQ | L42: Passed | M42: 45974 | N42: KhoiVN
...

Sheet Schedule Management
A2: Feature | B2: Schedule Management | R2: Passed
A3: Test requirement | B3: Verifies the complete schedule management flow—including creating, editing, assigning, and updating daily bus schedules—covering input validation, time/route consistency, conflict detection, role-based permissions, and reliable system updates. | R3: Failed
A4: Number of TCs | B4: =COUNTA(A12:A979)-6 -> 125 | R4: Pending
A5: Testing Round | B5: Passed | C5: Failed | D5: Pending | E5: N/A | R5: N/A
A6: Round 1 | B6: =COUNTIF($F10:$F1026,B5) -> 97 | C6: =COUNTIF($F10:$F1026,C5) -> 28 | D6: =COUNTIF($F9:$F976,D4) -> 0 | E6: =COUNTIF($F9:$F976,E4) -> 0
A7: Round 2 | B7: =COUNTIF($I10:$I977,B5) -> 121 | C7: =COUNTIF($I10:$I977,C5) -> 4 | D7: =COUNTIF($F10:$F977,D5) -> 0 | E7: =COUNTIF($F10:$F977,E5) -> 0
A8: Round 3 | B8: =COUNTIF($L10:$L977,B5) -> 122 | C8: =COUNTIF($L10:$L977,C5) -> 3 | D8: =COUNTIF($F10:$F977,D5) -> 0 | E8: =COUNTIF($F10:$F977,E5) -> 0
A10: Test Case ID | B10: Test Case Description | C10: Test Case Procedure | D10: Expected Results | E10: Pre-conditions | F10: Round 1 | G10: Test date | H10: Tester | I10: Round 2 | J10: Test date | K10: Tester | L10: Round 3 | M10: Test date | N10: Tester | O10: Note
A11: Create Schedule
A12: SCHED-001 | B12: Create schedule with valid data | C12: 1. Click "Create Schedule" button 2. Fill all required fields (name, type, start/end time, academic year, effective dates) 3. Select RRule pattern 4. Click "Save" | D12: 1. Success message "Schedule created successfully" 2. Schedule appears in list 3. Modal closes | E12: 1. User logged in as admin 2. Academic years available | F12: Passed | G12: 45928 | H12: HuyNLQ | I12: Passed | J12: 45960 | K12: TrungNVT | L12: Failed | M12: 45986 | N12: HuyNLQ
A13: SCHED-002 | B13: Create schedule with missing required field | C13: 1. Click "Create Schedule" 2. Leave "Schedule Name" field empty 3. Fill other required fields 4. Click "Save" | D13: 1. Validation message "Schedule name is required" 2. Form submission blocked | E13: None | F13: Passed | G13: 45928 | H13: HuyNLQ | I13: Passed | J13: 45960 | K13: TrungNVT | L13: Passed | M13: 45986 | N13: HuyNLQ
A14: SCHED-003 | B14: Create schedule with invalid time range | C14: 1. Click "Create Schedule" 2. Set start time: 14:00 3. Set end time: 12:00 4. Fill other fields 5. Click "Save" | D14: 1. Validation message "End time must be after start time" 2. Form submission blocked | E14: None | F14: Passed | G14: 45928 | H14: HuyNLQ | I14: Passed | J14: 45960 | K14: TrungNVT | L14: Passed | M14: 45986 | N14: HuyNLQ
